Workbook
Name AW: _xlfn.ANCHORARRAY('STD All'!$AW$2)
Name AX: _xlfn.ANCHORARRAY('STD All'!$AX$2)
Name BA: _xlfn.ANCHORARRAY('STD All'!$BA$2)
Name BB: _xlfn.ANCHORARRAY('STD All'!$BB$2)
Name BC: _xlfn.ANCHORARRAY('STD All'!$BC$2)
Name BD: _xlfn.ANCHORARRAY('STD All'!$BD$2)
Name BE: _xlfn.ANCHORARRAY('STD All'!$BE$2)
Name BF: _xlfn.ANCHORARRAY('STD All'!$BF$2)
Name BG: _xlfn.ANCHORARRAY('STD All'!$BH$2)
Name BH: _xlfn.ANCHORARRAY('STD All'!$BI$2)
Name BI: _xlfn.ANCHORARRAY('STD All'!$BJ$2)
Name BJ: _xlfn.ANCHORARRAY('STD All'!$BK$2)
Name BK: _xlfn.ANCHORARRAY('STD All'!$BL$2)
Name BL: _xlfn.ANCHORARRAY('STD All'!$BM$2)
Name BM: _xlfn.ANCHORARRAY('STD All'!$BN$2)
Name BN: _xlfn.ANCHORARRAY('STD All'!$BO$2)
Name BO: _xlfn.ANCHORARRAY('STD All'!$BP$2)
Name BP: _xlfn.ANCHORARRAY('STD All'!$BQ$2)
Name BQ: _xlfn.ANCHORARRAY('STD All'!$BR$2)
Name BR: _xlfn.ANCHORARRAY('STD All'!$BS$2)
Name BS: _xlfn.ANCHORARRAY('STD All'!$BT$2)
Name BT: _xlfn.ANCHORARRAY('STD All'!$BU$2)
Name BU: _xlfn.ANCHORARRAY('STD All'!$BV$2)
Name BV: _xlfn.ANCHORARRAY('STD All'!$BW$2)
Name BW: _xlfn.ANCHORARRAY('STD All'!$BX$2)
Name BX: _xlfn.ANCHORARRAY('STD All'!$BY$2)
Name BY: _xlfn.ANCHORARRAY('STD All'!$BZ$2)
Name BZ: _xlfn.ANCHORARRAY('STD All'!$CA$2)
Name CA: _xlfn.ANCHORARRAY('STD All'!$CB$2)
Name CB: _xlfn.ANCHORARRAY('STD All'!$CC$2)
Name CC: _xlfn.ANCHORARRAY('STD All'!$CD$2)
Name CD: _xlfn.ANCHORARRAY('STD All'!$CE$2)
Name CE: _xlfn.ANCHORARRAY('STD All'!$CF$2)
Name CF: _xlfn.ANCHORARRAY('STD All'!$CG$2)
Name CG: _xlfn.ANCHORARRAY('STD All'!$CH$2)
Name CH: _xlfn.ANCHORARRAY('STD All'!$CI$2)
Name CI: _xlfn.ANCHORARRAY('STD All'!$CJ$2)
Name CJ: _xlfn.ANCHORARRAY('STD All'!$CK$2)
Name CK: _xlfn.ANCHORARRAY('STD All'!$CL$2)
Name CL: _xlfn.ANCHORARRAY('STD All'!$CM$2)
Name CM: _xlfn.ANCHORARRAY('STD All'!$CN$2)
Name CN: _xlfn.ANCHORARRAY('STD All'!$CO$2)
Name CO: _xlfn.ANCHORARRAY('STD All'!$CP$2)
Name CP: _xlfn.ANCHORARRAY('STD All'!$CQ$2)
Name CQ: _xlfn.ANCHORARRAY('STD All'!$CR$2)
Name CR: _xlfn.ANCHORARRAY('STD All'!$CS$2)
Name CS: _xlfn.ANCHORARRAY('STD All'!$CT$2)
Name CT: _xlfn.ANCHORARRAY('STD All'!$CU$2)
Name CU: _xlfn.ANCHORARRAY('STD All'!$CV$2)
Name CV: _xlfn.ANCHORARRAY('STD All'!$CW$2)
Name CW: _xlfn.ANCHORARRAY('STD All'!$CX$2)
Name CX: _xlfn.ANCHORARRAY('STD All'!$CY$2)
Name CY: _xlfn.ANCHORARRAY('STD All'!$CZ$2)
Name CZ: _xlfn.ANCHORARRAY('STD All'!$DA$2)
Name DA: _xlfn.ANCHORARRAY('STD All'!$DB$2)
Name DB: _xlfn.ANCHORARRAY('STD All'!$DC$2)
Name DC: _xlfn.ANCHORARRAY('STD All'!$DD$2)
Name DD: _xlfn.ANCHORARRAY('STD All'!$DE$2)
Name DE: _xlfn.ANCHORARRAY('STD All'!$DF$2)
Name DF: _xlfn.ANCHORARRAY('STD All'!$DG$2)

Sheet STD All
A1: TEST | B1: STD Value | C1: STD value | D1: =IF(H3="&","Sigma σ (&)","Sigma σ (or)") -> Sigma σ (&) | E1: TEST | F1: STD Value | G1: Tolerance | J1: QC restriction | AY1: Filename | AZ1: Lot nr | BA1: Lot | BB1: TEST | BC1: STD Value | BD1: M1 Readings | BE1: M2 Readings | BF1: M3 Readings | BG1: QC Date | BH1: LOT | BI1: LOT nr | BJ1: STD1 | BK1: STD2 | BL1: STD3 | BM1: STD4 | BN1: STD5 | BO1: STD6 | BP1: STD1 AVG | BQ1: STD2 AVG | BR1: STD3 AVG | BS1: STD4 AVG | BT1: STD5 AVG | BU1: STD6 AVG | BV1: Base1 | BW1: STD1 3σ low | BX1: STD1 2σ low | BY1: STD1 1σ low | BZ1: STD1 1σ high | CA1: STD1 2σ high | CB1: STD1 3σ high | CC1: Base2 | CD1: STD2 3σ low | CE1: STD2 2σ low | CF1: STD2 1σ low | CG1: STD2 1σ high | CH1: STD2 2σ high | CI1: STD2 3σ high | CJ1: Base3 | CK1: STD3 3σ low | CL1: STD3 2σ low | CM1: STD3 1σ low | CN1: STD3 1σ high | CO1: STD3 2σ high | CP1: STD3 3σ high | CQ1: Base4 | CR1: STD4 3σ low | CS1: STD4 2σ low | CT1: STD4 1σ low | CU1: STD4 1σ high | CV1: STD4 2σ high | CW1: STD4 3σ high | CX1: Base5 | CY1: STD5 3σ low | CZ1: STD5 2σ low | DA1: STD5 1σ low | DB1: STD5 1σ high | DC1: STD5 2σ high | DD1: STD5 3σ high | DE1: Base6 | DF1: STD6 3σ low | DG1: STD6 2σ low | DH1: STD6 1σ low | DI1: STD6 1σ high | DJ1: STD6 2σ high | DK1: STD6 3σ high | DL1: STD1 AVG | DM1: STD2 AVG | DN1: STD3 AVG | DO1: STD4 AVG | DP1: STD5 AVG | DQ1: STD6 AVG | DR1: STD1 AVG | DS1: STD2 AVG | DT1: STD3 AVG | DU1: STD4 AVG | DV1: STD5 AVG | DW1: STD6 AVG | DX1: STD1 AVG | DY1: STD2 AVG | DZ1: STD3 AVG | EA1: STD4 AVG | EB1: STD5 AVG | EC1: STD6 AVG
A2: {=_xlfn.VSTACK("---",_xlfn._xlws.FILTER(_xlfn._xlws.SORT(_xlfn.UNIQUE(' Import Lots Data'!E:E)),(_xlfn._xlws.SORT(_xlfn.UNIQUE(' Import Lots Data'!E:E))<>"TEST")*(_xlfn._xlws.SORT(_xlfn.UNIQUE(' Import Lots Data'!E:E))<>0)))} -> --- | B2: {=_xlfn.VSTACK("---",_xlfn._xlws.FILTER(_xlfn._xlws.SORT(_xlfn.UNIQUE(' Import Lots Data'!C:C)),(_xlfn._xlws.SORT(_xlfn.UNIQUE(' Import Lots Data'!C:C))<>"STD Value")*(_xlfn._xlws.SORT(_xlfn.UNIQUE(' Import Lots Data'!C:C))<>"")))} -> --- | C2: {=_xlfn._xlws.FILTER(_xlfn._xlws.SORT(_xlfn.UNIQUE(' Import Lots Data'!C:C)),(_xlfn._xlws.SORT(_xlfn.UNIQUE(' Import Lots Data'!C:C))<>"STD Value")*(_xlfn._xlws.SORT(_xlfn.UNIQUE(' Import Lots Data'!C:C))<>""))} -> 0 | D2: {=IF(_xlfn.ANCHORARRAY(C2)<>"",IF(H3="&",$G$3*50%+_xlfn.ANCHORARRAY(C2)*$I$3*50%,IF($G$3*50%>(_xlfn.ANCHORARRAY(C2)*$I$3)*50%,$G$3*50%,(_xlfn.ANCHORARRAY(C2)*$I$3)*50%)),"")} -> 1 | E2: P/Final | F2: 0 | G2: Fixed | H2: & / or | I2: Percent | J2: ='Import Hanna Code'!L39 -> 100% | AW2: {=_xlfn.NUMBERVALUE(_xlfn.ANCHORARRAY(BA2)+0.1)} -> 1.1 | AX2: {=_xlfn.NUMBERVALUE(_xlfn.ANCHORARRAY(BA2)+0.1)} -> 1.1 | AY2: {=IFERROR(_xlfn.SORTBY(_xlfn._xlws.FILTER(' Import Lots Data'!A:A,((' Import Lots Data'!E:E=E2)+(' Import Lots Data'!E:E=E3)+(' Import Lots Data'!E:E=E4)+(' Import Lots Data'!E:E=E5)+(' Import Lots Data'!E:E=E6)+(' Import Lots Data'!E:E=E7))*((' Import Lots Data'!C:C=F2)+(' Import Lots Data'!C:C=F3)+(' Import Lots Data'!C:C=F4)+(' Import Lots Data'!C:C=F5)+(' Import Lots Data'!C:C=F6)+(' Import Lots Data'!C:C=F7)),),_xlfn._xlws.FILTER(' Import Lots Data'!F:F,((' Import Lots Data'!E:E=E2)+(' Import Lots Data'!E:E=E3)+(' Import Lots Data'!E:E=E4)+(' Import Lots Data'!E:E=E5)+(' Import Lots Data'!E:E=E6)+(' Import Lots Data'!E:E=E7))*((' Import Lots Data'!C:C=F2)+(' Import Lots Data'!C:C=F3)+(' Import Lots Data'!C:C=F4)+(' Import Lots Data'!C:C=F5)+(' Import Lots Data'!C:C=F6)+(' Import Lots Data'!C:C=F7)),)),0)} -> R080_HI782-0_0.0_LOT0366_PWW49.1_QC.xlsx | AZ2: {=_xlfn.TEXTBEFORE(_xlfn.TEXTAFTER(_xlfn.ANCHORARRAY(AY2),"_",3),"_",1)} -> LOT0366 | BA2: {=_xlfn.NUMBERVALUE(_xlfn.XLOOKUP(_xlfn.ANCHORARRAY(AZ2),_xlfn.ANCHORARRAY(BH2),_xlfn.ANCHORARRAY(BI2)))} -> 1 | BB2: {=IFERROR(_xlfn.SORTBY(_xlfn._xlws.FILTER(' Import Lots Data'!E:E,((' Import Lots Data'!E:E=E2)+(' Import Lots Data'!E:E=E3)+(' Import Lots Data'!E:E=E4)+(' Import Lots Data'!E:E=E5)+(' Import Lots Data'!E:E=E6)+(' Import Lots Data'!E:E=E7))*((' Import Lots Data'!C:C=F2)+(' Import Lots Data'!C:C=F3)+(' Import Lots Data'!C:C=F4)+(' Import Lots Data'!C:C=F5)+(' Import Lots Data'!C:C=F6)+(' Import Lots Data'!C:C=F7)),),_xlfn._xlws.FILTER(' Import Lots Data'!F:F,((' Import Lots Data'!E:E=E2)+(' Import Lots Data'!E:E=E3)+(' Import Lots Data'!E:E=E4)+(' Import Lots Data'!E:E=E5)+(' Import Lots Data'!E:E=E6)+(' Import Lots Data'!E:E=E7))*((' Import Lots Data'!C:C=F2)+(' Import Lots Data'!C:C=F3)+(' Import Lots Data'!C:C=F4)+(' Import Lots Data'!C:C=F5)+(' Import Lots Data'!C:C=F6)+(' Import Lots Data'!C:C=F7)),)),0)} -> P/Final | BC2: {=_xlfn.NUMBERVALUE(IFERROR(_xlfn.SORTBY(_xlfn._xlws.FILTER(' Import Lots Data'!C:C,((' Import Lots Data'!E:E=E2)+(' Import Lots Data'!E:E=E3)+(' Import Lots Data'!E:E=E4)+(' Import Lots Data'!E:E=E5)+(' Import Lots Data'!E:E=E6)+(' Import Lots Data'!E:E=E7))*((' Import Lots Data'!C:C=F2)+(' Import Lots Data'!C:C=F3)+(' Import Lots Data'!C:C=F4)+(' Import Lots Data'!C:C=F5)+(' Import Lots Data'!C:C=F6)+(' Import Lots Data'!C:C=F7)),),_xlfn._xlws.FILTER(' Import Lots Data'!F:F,((' Import Lots Data'!E:E=E2)+(' Import Lots Data'!E:E=E3)+(' Import Lots Data'!E:E=E4)+(' Import Lots Data'!E:E=E5)+(' Import Lots Data'!E:E=E6)+(' Import Lots Data'!E:E=E7))*((' Import Lots Data'!C:C=F2)+(' Import Lots Data'!C:C=F3)+(' Import Lots Data'!C:C=F4)+(' Import Lots Data'!C:C=F5)+(' Import Lots Data'!C:C=F6)+(' Import Lots Data'!C:C=F7)),)),0))} -> 0 | BD2: {=_xlfn.NUMBERVALUE(IFERROR(_xlfn.SORTBY(_xlfn._xlws.FILTER(' Import Lots Data'!L:L,((' Import Lots Data'!E:E=E2)+(' Import Lots Data'!E:E=E3)+(' Import Lots Data'!E:E=E4)+(' Import Lots Data'!E:E=E5)+(' Import Lots Data'!E:E=E6)+(' Import Lots Data'!E:E=E7))*((' Import Lots Data'!C:C=F2)+(' Import Lots Data'!C:C=F3)+(' Import Lots Data'!C:C=F4)+(' Import Lots Data'!C:C=F5)+(' Import Lots Data'!C:C=F6)+(' Import Lots Data'!C:C=F7)),),_xlfn._xlws.FILTER(' Import Lots Data'!F:F,((' Import Lots Data'!E:E=E2)+(' Import Lots Data'!E:E=E3)+(' Import Lots Data'!E:E=E4)+(' Import Lots Data'!E:E=E5)+(' Import Lots Data'!E:E=E6)+(' Import Lots Data'!E:E=E7))*((' Import Lots Data'!C:C=F2)+(' Import Lots Data'!C:C=F3)+(' Import Lots Data'!C:C=F4)+(' Import Lots Data'!C:C=F5)+(' Import Lots Data'!C:C=F6)+(' Import Lots Data'!C:C=F7)),)),0))} -> 0.4 | BE2: {=_xlfn.NUMBERVALUE(IFERROR(_xlfn.SORTBY(_xlfn._xlws.FILTER(' Import Lots Data'!M:M,((' Import Lots Data'!E:E=E2)+(' Import Lots Data'!E:E=E3)+(' Import Lots Data'!E:E=E4)+(' Import Lots Data'!E:E=E5)+(' Import Lots Data'!E:E=E6)+(' Import Lots Data'!E:E=E7))*((' Import Lots Data'!C:C=F2)+(' Import Lots Data'!C:C=F3)+(' Import Lots Data'!C:C=F4)+(' Import Lots Data'!C:C=F5)+(' Import Lots Data'!C:C=F6)+(' Import Lots Data'!C:C=F7)),),_xlfn._xlws.FILTER(' Import Lots Data'!F:F,((' Import Lots Data'!E:E=E2)+(' Import Lots Data'!E:E=E3)+(' Import Lots Data'!E:E=E4)+(' Import Lots Data'!E:E=E5)+(' Import Lots Data'!E:E=E6)+(' Import Lots Data'!E:E=E7))*((' Import Lots Data'!C:C=F2)+(' Import Lots Data'!C:C=F3)+(' Import Lots Data'!C:C=F4)+(' Import Lots Data'!C:C=F5)+(' Import Lots Data'!C:C=F6)+(' Import Lots Data'!C:C=F7)),)),0))} -> 0 | BF2: {=_xlfn.NUMBERVALUE(IFERROR(_xlfn.SORTBY(_xlfn._xlws.FILTER(' Import Lots Data'!N:N,((' Import Lots Data'!E:E=E2)+(' Import Lots Data'!E:E=E3)+(' Import Lots Data'!E:E=E4)+(' Import Lots Data'!E:E=E5)+(' Import Lots Data'!E:E=E6)+(' Import Lots Data'!E:E=E7))*((' Import Lots Data'!C:C=F2)+(' Import Lots Data'!C:C=F3)+(' Import Lots Data'!C:C=F4)+(' Import Lots Data'!C:C=F5)+(' Import Lots Data'!C:C=F6)+(' Import Lots Data'!C:C=F7)),),_xlfn._xlws.FILTER(' Import Lots Data'!F:F,((' Import Lots Data'!E:E=E2)+(' Import Lots Data'!E:E=E3)+(' Import Lots Data'!E:E=E4)+(' Import Lots Data'!E:E=E5)+(' Import Lots Data'!E:E=E6)+(' Import Lots Data'!E:E=E7))*((' Import Lots Data'!C:C=F2)+(' Import Lots Data'!C:C=F3)+(' Import Lots Data'!C:C=F4)+(' Import Lots Data'!C:C=F5)+(' Import Lots Data'!C:C=F6)+(' Import Lots Data'!C:C=F7)),)),0))} -> 0 | BG2: {=_xlfn.NUMBERVALUE(IFERROR(_xlfn.SORTBY(_xlfn._xlws.FILTER(' Import Lots Data'!F:F,((' Import Lots Data'!E:E=E2)+(' Import Lots Data'!E:E=E3)+(' Import Lots Data'!E:E=E4)+(' Import Lots Data'!E:E=E5)+(' Import Lots Data'!E:E=E6)+(' Import Lots Data'!E:E=E7))*((' Import Lots Data'!C:C=F2)+(' Import Lots Data'!C:C=F3)+(' Import Lots Data'!C:C=F4)+(' Import Lots Data'!C:C=F5)+(' Import Lots Data'!C:C=F6)+(' Import Lots Data'!C:C=F7)),),_xlfn._xlws.FILTER(' Import Lots Data'!F:F,((' Import Lots Data'!E:E=E2)+(' Import Lots Data'!E:E=E3)+(' Import Lots Data'!E:E=E4)+(' Import Lots Data'!E:E=E5)+(' Import Lots Data'!E:E=E6)+(' Import Lots Data'!E:E=E7))*((' Import Lots Data'!C:C=F2)+(' Import Lots Data'!C:C=F3)+(' Import Lots Data'!C:C=F4)+(' Import Lots Data'!C:C=F5)+(' Import Lots Data'!C:C=F6)+(' Import Lots Data'!C:C=F7)),)),0))} -> 45299 | BH2: {=_xlfn.UNIQUE(_xlfn.ANCHORARRAY(AZ2),FALSE,FALSE)} -> LOT0366 | BI2: {=IF(_xlfn.ANCHORARRAY(BH2)<>"",_xlfn.NUMBERVALUE(ROW(_xlfn.ANCHORARRAY(BH2))-1),"")} -> 1 | BJ2: {=IF(_xlfn.ANCHORARRAY(BH2)<>"",IF(B3<>"",_xlfn.NUMBERVALUE(B3),""),"")} -> 0 | BK2: {=IF(_xlfn.ANCHORARRAY(BH2)<>"",IF(B4<>"",_xlfn.NUMBERVALUE(B4),""),"")} -> 15 | BL2: {=IF(_xlfn.ANCHORARRAY(BH2)<>"",IF(B5<>"",_xlfn.NUMBERVALUE(B5),""),"")} -> 35 | BM2: {=IF(_xlfn.ANCHORARRAY(BH2)<>"",IF(B6<>"",_xlfn.NUMBERVALUE(B6),""),"")} -> 60 | BN2: {=IF(_xlfn.ANCHORARRAY(BH2)<>"",IF(B7<>"",_xlfn.NUMBERVALUE(B7),""),"")} | BO2: {=IF(_xlfn.ANCHORARRAY(BH2)<>"",IF(B8<>"",_xlfn.NUMBERVALUE(B8),""),"")} | BP2: {=_xlfn._xlws.FILTER(DL2:DL200,BH2:BH200<>"")} -> 0.45 | BQ2: {=_xlfn._xlws.FILTER(DM2:DM200,BH2:BH200<>"")} -> 16.74 | BR2: {=_xlfn._xlws.FILTER(DN2:DN200,BH2:BH200<>"")} -> 38.2 | BS2: {=_xlfn._xlws.FILTER(DO2:DO200,BH2:BH200<>"")} -> 64.46 | BT2: {=_xlfn._xlws.FILTER(DP2:DP200,BH2:BH200<>"")} | BU2: {=_xlfn._xlws.FILTER(DQ2:DQ200,BH2:BH200<>"")} | BV2: {=IF(_xlfn.ANCHORARRAY(BH2)<>"",IF(C2-3*D2*J4<0,0,C2-3*D2*J4),"")} -> 0 | BW2: {=IF(_xlfn.ANCHORARRAY(BH2)<>"",IF(C2-D2*J4<0,0,D2*J4),"")} -> 0 | BX2: {=IF(_xlfn.ANCHORARRAY(BH2)<>"",IF(C2-D2*J4<0,0,D2*J4),"")} -> 0 | BY2: {=IF(_xlfn.ANCHORARRAY(BH2)<>"",IF(C2-D2*J4<0,0,D2*J4),"")} -> 0 | BZ2: {=IF(_xlfn.ANCHORARRAY(BH2)<>"",IF(D2*J4<0,0,D2*J4),"")} -> 1 | CA2: {=IF(_xlfn.ANCHORARRAY(BH2)<>"",IF(D2*J4<0,0,D2*J4),"")} -> 1 | CB2: {=IF(_xlfn.ANCHORARRAY(BH2)<>"",IF(D2*J4<0,0,D2*J4),"")} -> 1 | CC2: {=IF(_xlfn.ANCHORARRAY(BH2)<>"",C3-C2-3*D3-3*D2,"")} -> 7.8975 | CD2: {=IF(_xlfn.ANCHORARRAY(BH2)<>"",IF(D3*J4<0,0,D3*J4),"")} -> 1.3675 | CE2: {=IF(_xlfn.ANCHORARRAY(BH2)<>"",IF(D3*J4<0,0,D3*J4),"")} -> 1.3675 | CF2: {=IF(_xlfn.ANCHORARRAY(BH2)<>"",IF(D3*J4<0,0,D3*J4),"")} -> 1.3675 | CG2: {=IF(_xlfn.ANCHORARRAY(BH2)<>"",IF(D3*J4<0,0,D3*J4),"")} -> 1.3675 | CH2: {=IF(_xlfn.ANCHORARRAY(BH2)<>"",IF(D3*J4<0,0,D3*J4),"")} -> 1.3675 | CI2: {=IF(_xlfn.ANCHORARRAY(BH2)<>"",IF(D3*J4<0,0,D3*J4),"")} -> 1.3675 | CJ2: {=IF(_xlfn.ANCHORARRAY(BH2)<>"",C4-C3-3*D4-3*D3,"")} -> 10.325 | CK2: {=IF(_xlfn.ANCHORARRAY(BH2)<>"",IF(D4*J4<0,0,D4*J4),"")} -> 1.8575 | CL2: {=IF(_xlfn.ANCHORARRAY(BH2)<>"",IF(D4*J4<0,0,D4*J4),"")} -> 1.8575 | CM2: {=IF(_xlfn.ANCHORARRAY(BH2)<>"",IF(D4*J4<0,0,D4*J4),"")} -> 1.8575 | CN2: {=IF(_xlfn.ANCHORARRAY(BH2)<>"",IF(D4*J4<0,0,D4*J4),"")} -> 1.8575 | CO2: {=IF(_xlfn.ANCHORARRAY(BH2)<>"",IF(D4*J4<0,0,D4*J4),"")} -> 1.8575 | CP2: {=IF(_xlfn.ANCHORARRAY(BH2)<>"",IF(D4*J4<0,0,D4*J4),"")} -> 1.8575 | CQ2: {=IF(_xlfn.ANCHORARRAY(BH2)<>"",C5-C4-3*D5-3*D4,"")} -> 12.0175 | CR2: {=IF(_xlfn.ANCHORARRAY(BH2)<>"",IF(D5*J4<0,0,D5*J4),"")} -> 2.47 | CS2: {=IF(_xlfn.ANCHORARRAY(BH2)<>"",IF(D5*J4<0,0,D5*J4),"")} -> 2.47 | CT2: {=IF(_xlfn.ANCHORARRAY(BH2)<>"",IF(D5*J4<0,0,D5*J4),"")} -> 2.47 | CU2: {=IF(_xlfn.ANCHORARRAY(BH2)<>"",IF(D5*J4<0,0,D5*J4),"")} -> 2.47 | CV2: {=IF(_xlfn.ANCHORARRAY(BH2)<>"",IF(D5*J4<0,0,D5*J4),"")} -> 2.47 | CW2: {=IF(_xlfn.ANCHORARRAY(BH2)<>"",IF(D5*J4<0,0,D5*J4),"")} -> 2.47 | CX2: {=IF(_xlfn.ANCHORARRAY(BH2)<>"",C6-C5-3*D6-3*D5,"")} -> -67.41 | CY2: {=IF(_xlfn.ANCHORARRAY(BH2)<>"",IF(D6*J4<0,0,D6*J4),"")} -> 0 | CZ2: {=IF(_xlfn.ANCHORARRAY(BH2)<>"",IF(D6*J4<0,0,D6*J4),"")} -> 0 | DA2: {=IF(_xlfn.ANCHORARRAY(BH2)<>"",IF(D6*J4<0,0,D6*J4),"")} -> 0 | DB2: {=IF(_xlfn.ANCHORARRAY(BH2)<>"",IF(D6*J4<0,0,D6*J4),"")} -> 0 | DC2: {=IF(_xlfn.ANCHORARRAY(BH2)<>"",IF(D6*J4<0,0,D6*J4),"")} -> 0 | DD2: {=IF(_xlfn.ANCHORARRAY(BH2)<>"",IF(D6*J4<0,0,D6*J4),"")} -> 0 | DE2: {=IF(_xlfn.ANCHORARRAY(BH2)<>"",C7-C6-3*D7-3*D6,"")} -> 0 | DF2: {=IF(_xlfn.ANCHORARRAY(BH2)<>"",IF(D7*J4<0,0,D7*J4),"")} -> 0 | DG2: {=IF(_xlfn.ANCHORARRAY(BH2)<>"",IF(D7*J4<0,0,D7*J4),"")} -> 0 | DH2: {=IF(_xlfn.ANCHORARRAY(BH2)<>"",IF(D7*J4<0,0,D7*J4),"")} -> 0 | DI2: {=IF(_xlfn.ANCHORARRAY(BH2)<>"",IF(D7*J4<0,0,D7*J4),"")} -> 0 | DJ2: {=IF(_xlfn.ANCHORARRAY(BH2)<>"",IF(D7*J4<0,0,D7*J4),"")} -> 0 | DK2: {=IF(_xlfn.ANCHORARRAY(BH2)<>"",IF(D7*J4<0,0,D7*J4),"")} -> 0 | DL2: {=IF($BJ2<>"",IFERROR(AVERAGE(_xlfn._xlws.FILTER($BD:$BD,($BA:$BA=$BI2)*($BC:$BC=_xlfn.NUMBERVALUE($BJ2)))),""),"")} -> 0.45 | DM2: {=IF($BK2<>"",IFERROR(AVERAGE(_xlfn._xlws.FILTER($BD:$BD,($BA:$BA=$BI2)*($BC:$BC=_xlfn.NUMBERVALUE($BK2)))),""),"")} -> 16.74 | DN2: {=IF($BL2<>"",IFERROR(AVERAGE(_xlfn._xlws.FILTER($BD:$BD,($BA:$BA=$BI2)*($BC:$BC=_xlfn.NUMBERVALUE($BL2)))),""),"")} -> 38.2 | DO2: {=IF($BM2<>"",IFERROR(AVERAGE(_xlfn._xlws.FILTER($BD:$BD,($BA:$BA=$BI2)*($BC:$BC=_xlfn.NUMBERVALUE($BM2)))),""),"")} -> 64.46 | DP2: {=IF($BN2<>"",IFERROR(AVERAGE(_xlfn._xlws.FILTER($BD:$BD,($BA:$BA=$BI2)*($BC:$BC=_xlfn.NUMBERVALUE($BN2)))),""),"")} | DQ2: {=IF($BO2<>"",IFERROR(AVERAGE(_xlfn._xlws.FILTER($BD:$BD,($BA:$BA=$BI2)*($BC:$BC=_xlfn.NUMBERVALUE($BO2)))),""),"")} | DR2: {=_xlfn._xlws.FILTER(DX2:DX200,BH2:BH200<>"")} -> 0 | DS2: {=_xlfn._xlws.FILTER(DY2:DY200,BH2:BH200<>"")} -> 0 | DT2: {=_xlfn._xlws.FILTER(DZ2:DZ200,BH2:BH200<>"")} -> 0 | DU2: {=_xlfn._xlws.FILTER(EA2:EA200,BH2:BH200<>"")} -> 0 | DV2: {=_xlfn._xlws.FILTER(EB2:EB200,BH2:BH200<>"")} | DW2: {=_xlfn._xlws.FILTER(EC2:EC200,BH2:BH200<>"")} | DX2: {=IF($BJ2<>"",IFERROR(AVERAGE(_xlfn._xlws.FILTER($BE:$BE,($BA:$BA=$BI2)*($BC:$BC=_xlfn.NUMBERVALUE($BJ2)))),""),"")} -> 0 | DY2: {=IF($BK2<>"",IFERROR(AVERAGE(_xlfn._xlws.FILTER($BE:$BE,($BA:$BA=$BI2)*($BC:$BC=_xlfn.NUMBERVALUE($BK2)))),""),"")} -> 0 | DZ2: {=IF($BL2<>"",IFERROR(AVERAGE(_xlfn._xlws.FILTER($BE:$BE,($BA:$BA=$BI2)*($BC:$BC=_xlfn.NUMBERVALUE($BL2)))),""),"")} -> 0 | EA2: {=IF($BM2<>"",IFERROR(AVERAGE(_xlfn._xlws.FILTER($BE:$BE,($BA:$BA=$BI2)*($BC:$BC=_xlfn.NUMBERVALUE($BM2)))),""),"")} -> 0 | EB2: {=IF($BN2<>"",IFERROR(AVERAGE(_xlfn._xlws.FILTER($BE:$BE,($BA:$BA=$BI2)*($BC:$BC=_xlfn.NUMBERVALUE($BN2)))),""),"")} | EC2: {=IF($BO2<>"",IFERROR(AVERAGE(_xlfn._xlws.FILTER($BE:$BE,($BA:$BA=$BI2)*($BC:$BC=_xlfn.NUMBERVALUE($BO2)))),""),"")}
A3: ASTM | B3: 0 | C3: 15 | D3: 1.3675 | E3: P/Prod | F3: 15 | G3: ='Import Hanna Code'!I39 -> 2.0 | H3: ='Import Hanna Code'!J39 -> & | I3: ='Import Hanna Code'!K39 -> 4.9% | J3: Custom QC restriction | AW3: 1.1 | AX3: 1.1 | AY3: R080_HI782-0_0.0_LOT0366_PWW49.1_QC.xlsx | AZ3: LOT0366 | BA3: 1 | BB3: P/Final | BC3: 0 | BD3: 0.4 | BE3: 0 | BF3: 0 | BG3: 45299 | BH3: LOT0367 | BI3: 2 | BJ3: 0 | BK3: 15 | BL3: 35 | BM3: 60 | BP3: 0.525 | BQ3: 16.3 | BR3: 37.675 | BS3: 62.425 | BV3: 0 | BW3: 0 | BX3: 0 | BY3: 0 | BZ3: 1 | CA3: 1 | CB3: 1 | CC3: 7.8975 | CD3: 1.3675 | CE3: 1.3675 | CF3: 1.3675 | CG3: 1.3675 | CH3: 1.3675 | CI3: 1.3675 | CJ3: 10.325 | CK3: 1.8575 | CL3: 1.8575 | CM3: 1.8575 | CN3: 1.8575 | CO3: 1.8575 | CP3: 1.8575 | CQ3: 12.0175 | CR3: 2.47 | CS3: 2.47 | CT3: 2.47 | CU3: 2.47 | CV3: 2.47 | CW3: 2.47 | CX3: -67.41 | CY3: 0 | CZ3: 0 | DA3: 0 | DB3: 0 | DC3: 0 | DD3: 0 | DE3: 0 | DF3: 0 | DG3: 0 | DH3: 0 | DI3: 0 | DJ3: 0 | DK3: 0 | DL3: {=IF($BJ3<>"",IFERROR(AVERAGE(_xlfn._xlws.FILTER($BD:$BD,($BA:$BA=$BI3)*($BC:$BC=_xlfn.NUMBERVALUE($BJ3)))),""),"")} -> 0.525 | DM3: {=IF($BK3<>"",IFERROR(AVERAGE(_xlfn._xlws.FILTER($BD:$BD,($BA:$BA=$BI3)*($BC:$BC=_xlfn.NUMBERVALUE($BK3)))),""),"")} -> 16.3 | DN3: {=IF($BL3<>"",IFERROR(AVERAGE(_xlfn._xlws.FILTER($BD:$BD,($BA:$BA=$BI3)*($BC:$BC=_xlfn.NUMBERVALUE($BL3)))),""),"")} -> 37.675 | DO3: {=IF($BM3<>"",IFERROR(AVERAGE(_xlfn._xlws.FILTER($BD:$BD,($BA:$BA=$BI3)*($BC:$BC=_xlfn.NUMBERVALUE($BM3)))),""),"")} -> 62.425 | DP3: {=IF($BN3<>"",IFERROR(AVERAGE(_xlfn._xlws.FILTER($BD:$BD,($BA:$BA=$BI3)*($BC:$BC=_xlfn.NUMBERVALUE($BN3)))),""),"")} | DQ3: {=IF($BO3<>"",IFERROR(AVERAGE(_xlfn._xlws.FILTER($BD:$BD,($BA:$BA=$BI3)*($BC:$BC=_xlfn.NUMBERVALUE($BO3)))),""),"")} | DR3: 0 | DS3: 0 | DT3: 0 | DU3: 0 | DX3: {=IF($BJ3<>"",IFERROR(AVERAGE(_xlfn._xlws.FILTER($BE:$BE,($BA:$BA=$BI3)*($BC:$BC=_xlfn.NUMBERVALUE($BJ3)))),""),"")} -> 0 | DY3: {=IF($BK3<>"",IFERROR(AVERAGE(_xlfn._xlws.FILTER($BE:$BE,($BA:$BA=$BI3)*($BC:$BC=_xlfn.NUMBERVALUE($BK3)))),""),"")} -> 0 | DZ3: {=IF($BL3<>"",IFERROR(AVERAGE(_xlfn._xlws.FILTER($BE:$BE,($BA:$BA=$BI3)*($BC:$BC=_xlfn.NUMBERVALUE($BL3)))),""),"")} -> 0 | EA3: {=IF($BM3<>"",IFERROR(AVERAGE(_xlfn._xlws.FILTER($BE:$BE,($BA:$BA=$BI3)*($BC:$BC=_xlfn.NUMBERVALUE($BM3)))),""),"")} -> 0 | EB3: {=IF($BN3<>"",IFERROR(AVERAGE(_xlfn._xlws.FILTER($BE:$BE,($BA:$BA=$BI3)*($BC:$BC=_xlfn.NUMBERVALUE($BN3)))),""),"")} | EC3: {=IF($BO3<>"",IFERROR(AVERAGE(_xlfn._xlws.FILTER($BE:$BE,($BA:$BA=$BI3)*($BC:$BC=_xlfn.NUMBERVALUE($BO3)))),""),"")}
A4: ASTM D665 | B4: 15 | C4: 35 | D4: 1.8575 | E4: --- | F4: 35 | J4: 1 | AW4: 1.1 | AX4: 1.1 | AY4: R080_HI782-0_0.0_LOT0366_PWW49.1_QC.xlsx | AZ4: LOT0366 | BA4: 1 | BB4: P/Final | BC4: 0 | BD4: 0.4 | BE4: 0 | BF4: 0 | BG4: 45299 | BH4: LOT0418 | BI4: 3 | BJ4: 0 | BK4: 15 | BL4: 35 | BM4: 60 | BP4: 0 | BQ4: 16.230769 | BR4: 36.206667 | BS4: 64.05 | BV4: 0 | BW4: 0 | BX4: 0 | BY4: 0 | BZ4: 1 | CA4: 1 | CB4: 1 | CC4: 7.8975 | CD4: 1.3675 | CE4: 1.3675 | CF4: 1.3675 | CG4: 1.3675 | CH4: 1.3675 | CI4: 1.3675 | CJ4: 10.325 | CK4: 1.8575 | CL4: 1.8575 | CM4: 1.8575 | CN4: 1.8575 | CO4: 1.8575 | CP4: 1.8575 | CQ4: 12.0175 | CR4: 2.47 | CS4: 2.47 | CT4: 2.47 | CU4: 2.47 | CV4: 2.47 | CW4: 2.47 | CX4: -67.41 | CY4: 0 | CZ4: 0 | DA4: 0 | DB4: 0 | DC4: 0 | DD4: 0 | DE4: 0 | DF4: 0 | DG4: 0 | DH4: 0 | DI4: 0 | DJ4: 0 | DK4: 0 | DL4: {=IF($BJ4<>"",IFERROR(AVERAGE(_xlfn._xlws.FILTER($BD:$BD,($BA:$BA=$BI4)*($BC:$BC=_xlfn.NUMBERVALUE($BJ4)))),""),"")} -> 0 | DM4: {=IF($BK4<>"",IFERROR(AVERAGE(_xlfn._xlws.FILTER($BD:$BD,($BA:$BA=$BI4)*($BC:$BC=_xlfn.NUMBERVALUE($BK4)))),""),"")} -> 16.230769 | DN4: {=IF($BL4<>"",IFERROR(AVERAGE(_xlfn._xlws.FILTER($BD:$BD,($BA:$BA=$BI4)*($BC:$BC=_xlfn.NUMBERVALUE($BL4)))),""),"")} -> 36.206667 | DO4: {=IF($BM4<>"",IFERROR(AVERAGE(_xlfn._xlws.FILTER($BD:$BD,($BA:$BA=$BI4)*($BC:$BC=_xlfn.NUMBERVALUE($BM4)))),""),"")} -> 64.05 | DP4: {=IF($BN4<>"",IFERROR(AVERAGE(_xlfn._xlws.FILTER($BD:$BD,($BA:$BA=$BI4)*($BC:$BC=_xlfn.NUMBERVALUE($BN4)))),""),"")} | DQ4: {=IF($BO4<>"",IFERROR(AVERAGE(_xlfn._xlws.FILTER($BD:$BD,($BA:$BA=$BI4)*($BC:$BC=_xlfn.NUMBERVALUE($BO4)))),""),"")} | DR4: 0 | DS4: 0 | DT4: 0 | DU4: 0 | DX4: {=IF($BJ4<>"",IFERROR(AVERAGE(_xlfn._xlws.FILTER($BE:$BE,($BA:$BA=$BI4)*($BC:$BC=_xlfn.NUMBERVALUE($BJ4)))),""),"")} -> 0 | DY4: {=IF($BK4<>"",IFERROR(AVERAGE(_xlfn._xlws.FILTER($BE:$BE,($BA:$BA=$BI4)*($BC:$BC=_xlfn.NUMBERVALUE($BK4)))),""),"")} -> 0 | DZ4: {=IF($BL4<>"",IFERROR(AVERAGE(_xlfn._xlws.FILTER($BE:$BE,($BA:$BA=$BI4)*($BC:$BC=_xlfn.NUMBERVALUE($BL4)))),""),"")} -> 0 | EA4: {=IF($BM4<>"",IFERROR(AVERAGE(_xlfn._xlws.FILTER($BE:$BE,($BA:$BA=$BI4)*($BC:$BC=_xlfn.NUMBERVALUE($BM4)))),""),"")} -> 0 | EB4: {=IF($BN4<>"",IFERROR(AVERAGE(_xlfn._xlws.FILTER($BE:$BE,($BA:$BA=$BI4)*($BC:$BC=_xlfn.NUMBERVALUE($BN4)))),""),"")} | EC4: {=IF($BO4<>"",IFERROR(AVERAGE(_xlfn._xlws.FILTER($BE:$BE,($BA:$BA=$BI4)*($BC:$BC=_xlfn.NUMBERVALUE($BO4)))),""),"")}
A5: EPP:170mg | B5: 35 | C5: 60 | D5: 2.47 | E5: --- | F5: 60 | AW5: 1.1 | AX5: 1.1 | AY5: R080_HI782-0_0.0_LOT0366_PWW49.1_QC.xlsx | AZ5: LOT0366 | BA5: 1 | BB5: P/Final | BC5: 0 | BD5: 0.6 | BE5: 0 | BF5: 0 | BG5: 45299 | BH5: LOT0428 | BI5: 4 | BJ5: 0 | BK5: 15 | BL5: 35 | BM5: 60 | BP5: 0.13333333 | BQ5: 15.358824 | BR5: 35.238095 | BS5: 60.541176 | BV5: 0 | BW5: 0 | BX5: 0 | BY5: 0 | BZ5: 1 | CA5: 1 | CB5: 1 | CC5: 7.8975 | CD5: 1.3675 | CE5: 1.3675 | CF5: 1.3675 | CG5: 1.3675 | CH5: 1.3675 | CI5: 1.3675 | CJ5: 10.325 | CK5: 1.8575 | CL5: 1.8575 | CM5: 1.8575 | CN5: 1.8575 | CO5: 1.8575 | CP5: 1.8575 | CQ5: 12.0175 | CR5: 2.47 | CS5: 2.47 | CT5: 2.47 | CU5: 2.47 | CV5: 2.47 | CW5: 2.47 | CX5: -67.41 | CY5: 0 | CZ5: 0 | DA5: 0 | DB5: 0 | DC5: 0 | DD5: 0 | DE5: 0 | DF5: 0 | DG5: 0 | DH5: 0 | DI5: 0 | DJ5: 0 | DK5: 0 | DL5: {=IF($BJ5<>"",IFERROR(AVERAGE(_xlfn._xlws.FILTER($BD:$BD,($BA:$BA=$BI5)*($BC:$BC=_xlfn.NUMBERVALUE($BJ5)))),""),"")} -> 0.13333333 | DM5: {=IF($BK5<>"",IFERROR(AVERAGE(_xlfn._xlws.FILTER($BD:$BD,($BA:$BA=$BI5)*($BC:$BC=_xlfn.NUMBERVALUE($BK5)))),""),"")} -> 15.358824 | DN5: {=IF($BL5<>"",IFERROR(AVERAGE(_xlfn._xlws.FILTER($BD:$BD,($BA:$BA=$BI5)*($BC:$BC=_xlfn.NUMBERVALUE($BL5)))),""),"")} -> 35.238095 | DO5: {=IF($BM5<>"",IFERROR(AVERAGE(_xlfn._xlws.FILTER($BD:$BD,($BA:$BA=$BI5)*($BC:$BC=_xlfn.NUMBERVALUE($BM5)))),""),"")} -> 60.541176 | DP5: {=IF($BN5<>"",IFERROR(AVERAGE(_xlfn._xlws.FILTER($BD:$BD,($BA:$BA=$BI5)*($BC:$BC=_xlfn.NUMBERVALUE($BN5)))),""),"")} | DQ5: {=IF($BO5<>"",IFERROR(AVERAGE(_xlfn._xlws.FILTER($BD:$BD,($BA:$BA=$BI5)*($BC:$BC=_xlfn.NUMBERVALUE($BO5)))),""),"")} | DR5: 0 | DS5: 0 | DT5: 0 | DU5: 0 | DX5: {=IF($BJ5<>"",IFERROR(AVERAGE(_xlfn._xlws.FILTER($BE:$BE,($BA:$BA=$BI5)*($BC:$BC=_xlfn.NUMBERVALUE($BJ5)))),""),"")} -> 0 | DY5: {=IF($BK5<>"",IFERROR(AVERAGE(_xlfn._xlws.FILTER($BE:$BE,($BA:$BA=$BI5)*($BC:$BC=_xlfn.NUMBERVALUE($BK5)))),""),"")} -> 0 | DZ5: {=IF($BL5<>"",IFERROR(AVERAGE(_xlfn._xlws.FILTER($BE:$BE,($BA:$BA=$BI5)*($BC:$BC=_xlfn.NUMBERVALUE($BL5)))),""),"")} -> 0 | EA5: {=IF($BM5<>"",IFERROR(AVERAGE(_xlfn._xlws.FILTER($BE:$BE,($BA:$BA=$BI5)*($BC:$BC=_xlfn.NUMBERVALUE($BM5)))),""),"")} -> 0 | EB5: {=IF($BN5<>"",IFERROR(AVERAGE(_xlfn._xlws.FILTER($BE:$BE,($BA:$BA=$BI5)*($BC:$BC=_xlfn.NUMBERVALUE($BN5)))),""),"")} | EC5: {=IF($BO5<>"",IFERROR(AVERAGE(_xlfn._xlws.FILTER($BE:$BE,($BA:$BA=$BI5)*($BC:$BC=_xlfn.NUMBERVALUE($BO5)))),""),"")}
A6: EPP:171mg | B6: 60 | E6: --- | F6: --- | AW6: 1.1 | AX6: 1.1 | AY6: R080_HI782-0_0.0_LOT0366_PWW49.1_QC.xlsx | AZ6: LOT0366 | BA6: 1 | BB6: P/Final | BC6: 15 | BD6: 16.6 | BE6: 0 | BF6: 0 | BG6: 45299 | BH6: LOT0450 | BI6: 5 | BJ6: 0 | BK6: 15 | BL6: 35 | BM6: 60 | BP6: 0.6 | BQ6: 17.186957 | BR6: 38.442857 | BS6: 62.014286 | BV6: 0 | BW6: 0 | BX6: 0 | BY6: 0 | BZ6: 1 | CA6: 1 | CB6: 1 | CC6: 7.8975 | CD6: 1.3675 | CE6: 1.3675 | CF6: 1.3675 | CG6: 1.3675 | CH6: 1.3675 | CI6: 1.3675 | CJ6: 10.325 | CK6: 1.8575 | CL6: 1.8575 | CM6: 1.8575 | CN6: 1.8575 | CO6: 1.8575 | CP6: 1.8575 | CQ6: 12.0175 | CR6: 2.47 | CS6: 2.47 | CT6: 2.47 | CU6: 2.47 | CV6: 2.47 | CW6: 2.47 | CX6: -67.41 | CY6: 0 | CZ6: 0 | DA6: 0 | DB6: 0 | DC6: 0 | DD6: 0 | DE6: 0 | DF6: 0 | DG6: 0 | DH6: 0 | DI6: 0 | DJ6: 0 | DK6: 0 | DL6: {=IF($BJ6<>"",IFERROR(AVERAGE(_xlfn._xlws.FILTER($BD:$BD,($BA:$BA=$BI6)*($BC:$BC=_xlfn.NUMBERVALUE($BJ6)))),""),"")} -> 0.6 | DM6: {=IF($BK6<>"",IFERROR(AVERAGE(_xlfn._xlws.FILTER($BD:$BD,($BA:$BA=$BI6)*($BC:$BC=_xlfn.NUMBERVALUE($BK6)))),""),"")} -> 17.186957 | DN6: {=IF($BL6<>"",IFERROR(AVERAGE(_xlfn._xlws.FILTER($BD:$BD,($BA:$BA=$BI6)*($BC:$BC=_xlfn.NUMBERVALUE($BL6)))),""),"")} -> 38.442857 | DO6: {=IF($BM6<>"",IFERROR(AVERAGE(_xlfn._xlws.FILTER($BD:$BD,($BA:$BA=$BI6)*($BC:$BC=_xlfn.NUMBERVALUE($BM6)))),""),"")} -> 62.014286 | DP6: {=IF($BN6<>"",IFERROR(AVERAGE(_xlfn._xlws.FILTER($BD:$BD,($BA:$BA=$BI6)*($BC:$BC=_xlfn.NUMBERVALUE($BN6)))),""),"")} | DQ6: {=IF($BO6<>"",IFERROR(AVERAGE(_xlfn._xlws.FILTER($BD:$BD,($BA:$BA=$BI6)*($BC:$BC=_xlfn.NUMBERVALUE($BO6)))),""),"")} | DR6: 0 | DS6: 0 | DT6: 0 | DU6: 0 | DX6: {=IF($BJ6<>"",IFERROR(AVERAGE(_xlfn._xlws.FILTER($BE:$BE,($BA:$BA=$BI6)*($BC:$BC=_xlfn.NUMBERVALUE($BJ6)))),""),"")} -> 0 | DY6: {=IF($BK6<>"",IFERROR(AVERAGE(_xlfn._xlws.FILTER($BE:$BE,($BA:$BA=$BI6)*($BC:$BC=_xlfn.NUMBERVALUE($BK6)))),""),"")} -> 0 | DZ6: {=IF($BL6<>"",IFERROR(AVERAGE(_xlfn._xlws.FILTER($BE:$BE,($BA:$BA=$BI6)*($BC:$BC=_xlfn.NUMBERVALUE($BL6)))),""),"")} -> 0 | EA6: {=IF($BM6<>"",IFERROR(AVERAGE(_xlfn._xlws.FILTER($BE:$BE,($BA:$BA=$BI6)*($BC:$BC=_xlfn.NUMBERVALUE($BM6)))),""),"")} -> 0 | EB6: {=IF($BN6<>"",IFERROR(AVERAGE(_xlfn._xlws.FILTER($BE:$BE,($BA:$BA=$BI6)*($BC:$BC=_xlfn.NUMBERVALUE($BN6)))),""),"")} | EC6: {=IF($BO6<>"",IFERROR(AVERAGE(_xlfn._xlws.FILTER($BE:$BE,($BA:$BA=$BI6)*($BC:$BC=_xlfn.NUMBERVALUE($BO6)))),""),"")}
A7: EPP:172mg | E7: --- | F7: --- | AW7: 1.1 | AX7: 1.1 | AY7: R080_HI782-0_0.0_LOT0366_PWW49.1_QC.xlsx | AZ7: LOT0366 | BA7: 1 | BB7: P/Final | BC7: 15 | BD7: 17.2 | BE7: 0 | BF7: 0 | BG7: 45299 | BH7: LOT0473 | BI7: 6 | BJ7: 0 | BK7: 15 | BL7: 35 | BM7: 60 | BP7: 0.35 | BQ7: 15.823077 | BR7: 37.15625 | BS7: 59.409091 | BV7: 0 | BW7: 0 | BX7: 0 | BY7: 0 | BZ7: 1 | CA7: 1 | CB7: 1 | CC7: 7.8975 | CD7: 1.3675 | CE7: 1.3675 | CF7: 1.3675 | CG7: 1.3675 | CH7: 1.3675 | CI7: 1.3675 | CJ7: 10.325 | CK7: 1.8575 | CL7: 1.8575 | CM7: 1.8575 | CN7: 1.8575 | CO7: 1.8575 | CP7: 1.8575 | CQ7: 12.0175 | CR7: 2.47 | CS7: 2.47 | CT7: 2.47 | CU7: 2.47 | CV7: 2.47 | CW7: 2.47 | CX7: -67.41 | CY7: 0 | CZ7: 0 | DA7: 0 | DB7: 0 | DC7: 0 | DD7: 0 | DE7: 0 | DF7: 0 | DG7: 0 | DH7: 0 | DI7: 0 | DJ7: 0 | DK7: 0 | DL7: {=IF($BJ7<>"",IFERROR(AVERAGE(_xlfn._xlws.FILTER($BD:$BD,($BA:$BA=$BI7)*($BC:$BC=_xlfn.NUMBERVALUE($BJ7)))),""),"")} -> 0.35 | DM7: {=IF($BK7<>"",IFERROR(AVERAGE(_xlfn._xlws.FILTER($BD:$BD,($BA:$BA=$BI7)*($BC:$BC=_xlfn.NUMBERVALUE($BK7)))),""),"")} -> 15.823077 | DN7: {=IF($BL7<>"",IFERROR(AVERAGE(_xlfn._xlws.FILTER($BD:$BD,($BA:$BA=$BI7)*($BC:$BC=_xlfn.NUMBERVALUE($BL7)))),""),"")} -> 37.15625 | DO7: {=IF($BM7<>"",IFERROR(AVERAGE(_xlfn._xlws.FILTER($BD:$BD,($BA:$BA=$BI7)*($BC:$BC=_xlfn.NUMBERVALUE($BM7)))),""),"")} -> 59.409091 | DP7: {=IF($BN7<>"",IFERROR(AVERAGE(_xlfn._xlws.FILTER($BD:$BD,($BA:$BA=$BI7)*($BC:$BC=_xlfn.NUMBERVALUE($BN7)))),""),"")} | DQ7: {=IF($BO7<>"",IFERROR(AVERAGE(_xlfn._xlws.FILTER($BD:$BD,($BA:$BA=$BI7)*($BC:$BC=_xlfn.NUMBERVALUE($BO7)))),""),"")} | DR7: 0 | DS7: 0 | DT7: 0 | DU7: 0 | DX7: {=IF($BJ7<>"",IFERROR(AVERAGE(_xlfn._xlws.FILTER($BE:$BE,($BA:$BA=$BI7)*($BC:$BC=_xlfn.NUMBERVALUE($BJ7)))),""),"")} -> 0 | DY7: {=IF($BK7<>"",IFERROR(AVERAGE(_xlfn._xlws.FILTER($BE:$BE,($BA:$BA=$BI7)*($BC:$BC=_xlfn.NUMBERVALUE($BK7)))),""),"")} -> 0 | DZ7: {=IF($BL7<>"",IFERROR(AVERAGE(_xlfn._xlws.FILTER($BE:$BE,($BA:$BA=$BI7)*($BC:$BC=_xlfn.NUMBERVALUE($BL7)))),""),"")} -> 0 | EA7: {=IF($BM7<>"",IFERROR(AVERAGE(_xlfn._xlws.FILTER($BE:$BE,($BA:$BA=$BI7)*($BC:$BC=_xlfn.NUMBERVALUE($BM7)))),""),"")} -> 0 | EB7: {=IF($BN7<>"",IFERROR(AVERAGE(_xlfn._xlws.FILTER($BE:$BE,($BA:$BA=$BI7)*($BC:$BC=_xlfn.NUMBERVALUE($BN7)))),""),"")} | EC7: {=IF($BO7<>"",IFERROR(AVERAGE(_xlfn._xlws.FILTER($BE:$BE,($BA:$BA=$BI7)*($BC:$BC=_xlfn.NUMBERVALUE($BO7)))),""),"")}
A8: EPP:250mg | AW8: 1.1 | AX8: 1.1 | AY8: R080_HI782-0_0.0_LOT0366_PWW49.1_QC.xlsx | AZ8: LOT0366 | BA8: 1 | BB8: P/Final | BC8: 15 | BD8: 17 | BE8: 0 | BF8: 0 | BG8: 45299 | BH8: LOT0504 | BI8: 7 | BJ8: 0 | BK8: 15 | BL8: 35 | BM8: 60 | BP8: 0 | BQ8: 16.478947 | BR8: 37.93913 | BS8: 62.090476 | BV8: 0 | BW8: 0 | BX8: 0 | BY8: 0 | BZ8: 1 | CA8: 1 | CB8: 1 | CC8: 7.8975 | CD8: 1.3675 | CE8: 1.3675 | CF8: 1.3675 | CG8: 1.3675 | CH8: 1.3675 | CI8: 1.3675 | CJ8: 10.325 | CK8: 1.8575 | CL8: 1.8575 | CM8: 1.8575 | CN8: 1.8575 | CO8: 1.8575 | CP8: 1.8575 | CQ8: 12.0175 | CR8: 2.47 | CS8: 2.47 | CT8: 2.47 | CU8: 2.47 | CV8: 2.47 | CW8: 2.47 | CX8: -67.41 | CY8: 0 | CZ8: 0 | DA8: 0 | DB8: 0 | DC8: 0 | DD8: 0 | DE8: 0 | DF8: 0 | DG8: 0 | DH8: 0 | DI8: 0 | DJ8: 0 | DK8: 0 | DL8: {=IF($BJ8<>"",IFERROR(AVERAGE(_xlfn._xlws.FILTER($BD:$BD,($BA:$BA=$BI8)*($BC:$BC=_xlfn.NUMBERVALUE($BJ8)))),""),"")} -> 0 | DM8: {=IF($BK8<>"",IFERROR(AVERAGE(_xlfn._xlws.FILTER($BD:$BD,($BA:$BA=$BI8)*($BC:$BC=_xlfn.NUMBERVALUE($BK8)))),""),"")} -> 16.478947 | DN8: {=IF($BL8<>"",IFERROR(AVERAGE(_xlfn._xlws.FILTER($BD:$BD,($BA:$BA=$BI8)*($BC:$BC=_xlfn.NUMBERVALUE($BL8)))),""),"")} -> 37.93913 | DO8: {=IF($BM8<>"",IFERROR(AVERAGE(_xlfn._xlws.FILTER($BD:$BD,($BA:$BA=$BI8)*($BC:$BC=_xlfn.NUMBERVALUE($BM8)))),""),"")} -> 62.090476 | DP8: {=IF($BN8<>"",IFERROR(AVERAGE(_xlfn._xlws.FILTER($BD:$BD,($BA:$BA=$BI8)*($BC:$BC=_xlfn.NUMBERVALUE($BN8)))),""),"")} | DQ8: {=IF($BO8<>"",IFERROR(AVERAGE(_xlfn._xlws.FILTER($BD:$BD,($BA:$BA=$BI8)*($BC:$BC=_xlfn.NUMBERVALUE($BO8)))),""),"")} | DR8: 0 | DS8: 0 | DT8: 0 | DU8: 0 | DX8: {=IF($BJ8<>"",IFERROR(AVERAGE(_xlfn._xlws.FILTER($BE:$BE,($BA:$BA=$BI8)*($BC:$BC=_xlfn.NUMBERVALUE($BJ8)))),""),"")} -> 0 | DY8: {=IF($BK8<>"",IFERROR(AVERAGE(_xlfn._xlws.FILTER($BE:$BE,($BA:$BA=$BI8)*($BC:$BC=_xlfn.NUMBERVALUE($BK8)))),""),"")} -> 0 | DZ8: {=IF($BL8<>"",IFERROR(AVERAGE(_xlfn._xlws.FILTER($BE:$BE,($BA:$BA=$BI8)*($BC:$BC=_xlfn.NUMBERVALUE($BL8)))),""),"")} -> 0 | EA8: {=IF($BM8<>"",IFERROR(AVERAGE(_xlfn._xlws.FILTER($BE:$BE,($BA:$BA=$BI8)*($BC:$BC=_xlfn.NUMBERVALUE($BM8)))),""),"")} -> 0 | EB8: {=IF($BN8<>"",IFERROR(AVERAGE(_xlfn._xlws.FILTER($BE:$BE,($BA:$BA=$BI8)*($BC:$BC=_xlfn.NUMBERVALUE($BN8)))),""),"")} | EC8: {=IF($BO8<>"",IFERROR(AVERAGE(_xlfn._xlws.FILTER($BE:$BE,($BA:$BA=$BI8)*($BC:$BC=_xlfn.NUMBERVALUE($BO8)))),""),"")}
A9: Old A | AW9: 1.1 | AX9: 1.1 | AY9: R080_HI782-0_0.0_LOT0366_PWW49.1_QC.xlsx | AZ9: LOT0366 | BA9: 1 | BB9: P/Final | BC9: 15 | BD9: 15.7 | BE9: 0 | BF9: 0 | BG9: 45299 | BH9: LOT0512 | BI9: 8 | BJ9: 0 | BK9: 15 | BL9: 35 | BM9: 60 | BP9: 0.1 | BQ9: 16.36 | BR9: 38 | BS9: 63.14 | BV9: 0 | BW9: 0 | BX9: 0 | BY9: 0 | BZ9: 1 | CA9: 1 | CB9: 1 | CC9: 7.8975 | CD9: 1.3675 | CE9: 1.3675 | CF9: 1.3675 | CG9: 1.3675 | CH9: 1.3675 | CI9: 1.3675 | CJ9: 10.325 | CK9: 1.8575 | CL9: 1.8575 | CM9: 1.8575 | CN9: 1.8575 | CO9: 1.8575 | CP9: 1.8575 | CQ9: 12.0175 | CR9: 2.47 | CS9: 2.47 | CT9: 2.47 | CU9: 2.47 | CV9: 2.47 | CW9: 2.47 | CX9: -67.41 | CY9: 0 | CZ9: 0 | DA9: 0 | DB9: 0 | DC9: 0 | DD9: 0 | DE9: 0 | DF9: 0 | DG9: 0 | DH9: 0 | DI9: 0 | DJ9: 0 | DK9: 0 | DL9: {=IF($BJ9<>"",IFERROR(AVERAGE(_xlfn._xlws.FILTER($BD:$BD,($BA:$BA=$BI9)*($BC:$BC=_xlfn.NUMBERVALUE($BJ9)))),""),"")} -> 0.1 | DM9: {=IF($BK9<>"",IFERROR(AVERAGE(_xlfn._xlws.FILTER($BD:$BD,($BA:$BA=$BI9)*($BC:$BC=_xlfn.NUMBERVALUE($BK9)))),""),"")} -> 16.36 | DN9: {=IF($BL9<>"",IFERROR(AVERAGE(_xlfn._xlws.FILTER($BD:$BD,($BA:$BA=$BI9)*($BC:$BC=_xlfn.NUMBERVALUE($BL9)))),""),"")} -> 38 | DO9: {=IF($BM9<>"",IFERROR(AVERAGE(_xlfn._xlws.FILTER($BD:$BD,($BA:$BA=$BI9)*($BC:$BC=_xlfn.NUMBERVALUE($BM9)))),""),"")} -> 63.14 | DP9: {=IF($BN9<>"",IFERROR(AVERAGE(_xlfn._xlws.FILTER($BD:$BD,($BA:$BA=$BI9)*($BC:$BC=_xlfn.NUMBERVALUE($BN9)))),""),"")} | DQ9: {=IF($BO9<>"",IFERROR(AVERAGE(_xlfn._xlws.FILTER($BD:$BD,($BA:$BA=$BI9)*($BC:$BC=_xlfn.NUMBERVALUE($BO9)))),""),"")} | DR9: 0 | DS9: 0 | DT9: 0 | DU9: 0 | DX9: {=IF($BJ9<>"",IFERROR(AVERAGE(_xlfn._xlws.FILTER($BE:$BE,($BA:$BA=$BI9)*($BC:$BC=_xlfn.NUMBERVALUE($BJ9)))),""),"")} -> 0 | DY9: {=IF($BK9<>"",IFERROR(AVERAGE(_xlfn._xlws.FILTER($BE:$BE,($BA:$BA=$BI9)*($BC:$BC=_xlfn.NUMBERVALUE($BK9)))),""),"")} -> 0 | DZ9: {=IF($BL9<>"",IFERROR(AVERAGE(_xlfn._xlws.FILTER($BE:$BE,($BA:$BA=$BI9)*($BC:$BC=_xlfn.NUMBERVALUE($BL9)))),""),"")} -> 0 | EA9: {=IF($BM9<>"",IFERROR(AVERAGE(_xlfn._xlws.FILTER($BE:$BE,($BA:$BA=$BI9)*($BC:$BC=_xlfn.NUMBERVALUE($BM9)))),""),"")} -> 0 | EB9: {=IF($BN9<>"",IFERROR(AVERAGE(_xlfn._xlws.FILTER($BE:$BE,($BA:$BA=$BI9)*($BC:$BC=_xlfn.NUMBERVALUE($BN9)))),""),"")} | EC9: {=IF($BO9<>"",IFERROR(AVERAGE(_xlfn._xlws.FILTER($BE:$BE,($BA:$BA=$BI9)*($BC:$BC=_xlfn.NUMBERVALUE($BO9)))),""),"")}
A10: Old B | K10: =CONCATENATE("Std 1 tests distribution( ",C2," )" ) -> Std 1 tests distribution( 0 ) | T10: =CONCATENATE("Std 2 tests distribution( ",C3," )") -> Std 2 tests distribution( 15 ) | AC10: =CONCATENATE("Std 3 tests distribution( ",C4," )" ) -> Std 3 tests distribution( 35 ) | AL10: =CONCATENATE("Std 4 tests distribution( ",C5," )" ) -> Std 4 tests distribution( 60 ) | AW10: 1.1 | AX10: 1.1 | AY10: R080_HI782-0_0.0_LOT0366_PWW49.1_QC.xlsx | AZ10: LOT0366 | BA10: 1 | BB10: P/Final | BC10: 15 | BD10: 17.2 | BE10: 0 | BF10: 0 | BG10: 45299 | BH10: LOT0548 | BI10: 9 | BJ10: 0 | BK10: 15 | BL10: 35 | BM10: 60 | BP10: 0 | BQ10: 16.452632 | BR10: 37.1 | BS10: 60.642105 | BV10: 0 | BW10: 0 | BX10: 0 | BY10: 0 | BZ10: 1 | CA10: 1 | CB10: 1 | CC10: 7.8975 | CD10: 1.3675 | CE10: 1.3675 | CF10: 1.3675 | CG10: 1.3675 | CH10: 1.3675 | CI10: 1.3675 | CJ10: 10.325 | CK10: 1.8575 | CL10: 1.8575 | CM10: 1.8575 | CN10: 1.8575 | CO10: 1.8575 | CP10: 1.8575 | CQ10: 12.0175 | CR10: 2.47 | CS10: 2.47 | CT10: 2.47 | CU10: 2.47 | CV10: 2.47 | CW10: 2.47 | CX10: -67.41 | CY10: 0 | CZ10: 0 | DA10: 0 | DB10: 0 | DC10: 0 | DD10: 0 | DE10: 0 | DF10: 0 | DG10: 0 | DH10: 0 | DI10: 0 | DJ10: 0 | DK10: 0 | DL10: {=IF($BJ10<>"",IFERROR(AVERAGE(_xlfn._xlws.FILTER($BD:$BD,($BA:$BA=$BI10)*($BC:$BC=_xlfn.NUMBERVALUE($BJ10)))),""),"")} -> 0 | DM10: {=IF($BK10<>"",IFERROR(AVERAGE(_xlfn._xlws.FILTER($BD:$BD,($BA:$BA=$BI10)*($BC:$BC=_xlfn.NUMBERVALUE($BK10)))),""),"")} -> 16.452632 | DN10: {=IF($BL10<>"",IFERROR(AVERAGE(_xlfn._xlws.FILTER($BD:$BD,($BA:$BA=$BI10)*($BC:$BC=_xlfn.NUMBERVALUE($BL10)))),""),"")} -> 37.1 | DO10: {=IF($BM10<>"",IFERROR(AVERAGE(_xlfn._xlws.FILTER($BD:$BD,($BA:$BA=$BI10)*($BC:$BC=_xlfn.NUMBERVALUE($BM10)))),""),"")} -> 60.642105 | DP10: {=IF($BN10<>"",IFERROR(AVERAGE(_xlfn._xlws.FILTER($BD:$BD,($BA:$BA=$BI10)*($BC:$BC=_xlfn.NUMBERVALUE($BN10)))),""),"")} | DQ10: {=IF($BO10<>"",IFERROR(AVERAGE(_xlfn._xlws.FILTER($BD:$BD,($BA:$BA=$BI10)*($BC:$BC=_xlfn.NUMBERVALUE($BO10)))),""),"")} | DR10: 0 | DS10: 0 | DT10: 0 | DU10: 0 | DX10: {=IF($BJ10<>"",IFERROR(AVERAGE(_xlfn._xlws.FILTER($BE:$BE,($BA:$BA=$BI10)*($BC:$BC=_xlfn.NUMBERVALUE($BJ10)))),""),"")} -> 0 | DY10: {=IF($BK10<>"",IFERROR(AVERAGE(_xlfn._xlws.FILTER($BE:$BE,($BA:$BA=$BI10)*($BC:$BC=_xlfn.NUMBERVALUE($BK10)))),""),"")} -> 0 | DZ10: {=IF($BL10<>"",IFERROR(AVERAGE(_xlfn._xlws.FILTER($BE:$BE,($BA:$BA=$BI10)*($BC:$BC=_xlfn.NUMBERVALUE($BL10)))),""),"")} -> 0 | EA10: {=IF($BM10<>"",IFERROR(AVERAGE(_xlfn._xlws.FILTER($BE:$BE,($BA:$BA=$BI10)*($BC:$BC=_xlfn.NUMBERVALUE($BM10)))),""),"")} -> 0 | EB10: {=IF($BN10<>"",IFERROR(AVERAGE(_xlfn._xlws.FILTER($BE:$BE,($BA:$BA=$BI10)*($BC:$BC=_xlfn.NUMBERVALUE($BN10)))),""),"")} | EC10: {=IF($BO10<>"",IFERROR(AVERAGE(_xlfn._xlws.FILTER($BE:$BE,($BA:$BA=$BI10)*($BC:$BC=_xlfn.NUMBERVALUE($BO10)))),""),"")}
A11: Old C | F11: Nr. | G11: Lot | H11: QC Date | I11: QC Week | J11: Grand total tests | K11: Total tests | L11: <1 σ | M11: <1 σ [%] | N11: 1 σ to 2 σ | O11: 1 σ to 2 σ [%] | P11: 2 σ to 3 σ | Q11: 2 σ to 3 σ [%] | R11: >3 σ | S11: >3 σ [%] | T11: Total tests | U11: <1 σ | V11: <1 σ [%] | W11: 1 σ to 2 σ | X11: 1 σ to 2 σ [%] | Y11: 2 σ to 3 σ | Z11: 2 σ to 3 σ [%] | AA11: >3 σ | AB11: >3 σ [%] | AC11: Total tests | AD11: <1 σ | AE11: <1 σ [%] | AF11: 1 σ to 2 σ | AG11: 1 σ to 2 σ [%] | AH11: 2 σ to 3 σ | AI11: 2 σ to 3 σ [%] | AJ11: >3 σ | AK11: >3 σ [%] | AL11: Total tests | AM11: <1 σ | AN11: <1 σ [%] | AO11: 1 σ to 2 σ | AP11: 1 σ to 2 σ [%] | AQ11: 2 σ to 3 σ | AR11: 2 σ to 3 σ [%] | AS11: >3 σ | AT11: >3 σ [%] | AW11: 1.1 | AX11: 1.1 | AY11: R080_HI782-0_0.0_LOT0366_PWW49.1_QC.xlsx | AZ11: LOT0366 | BA11: 1 | BB11: P/Final | BC11: 35 | BD11: 37.9 | BE11: 0 | BF11: 0 | BG11: 45299 | BH11: LOT0550 | BI11: 10 | BJ11: 0 | BK11: 15 | BL11: 35 | BM11: 60 | BP11: 0 | BQ11: 16.394444 | BR11: 35.916667 | BS11: 60.9 | BV11: 0 | BW11: 0 | BX11: 0 | BY11: 0 | BZ11: 1 | CA11: 1 | CB11: 1 | CC11: 7.8975 | CD11: 1.3675 | CE11: 1.3675 | CF11: 1.3675 | CG11: 1.3675 | CH11: 1.3675 | CI11: 1.3675 | CJ11: 10.325 | CK11: 1.8575 | CL11: 1.8575 | CM11: 1.8575 | CN11: 1.8575 | CO11: 1.8575 | CP11: 1.8575 | CQ11: 12.0175 | CR11: 2.47 | CS11: 2.47 | CT11: 2.47 | CU11: 2.47 | CV11: 2.47 | CW11: 2.47 | CX11: -67.41 | CY11: 0 | CZ11: 0 | DA11: 0 | DB11: 0 | DC11: 0 | DD11: 0 | DE11: 0 | DF11: 0 | DG11: 0 | DH11: 0 | DI11: 0 | DJ11: 0 | DK11: 0 | DL11: {=IF($BJ11<>"",IFERROR(AVERAGE(_xlfn._xlws.FILTER($BD:$BD,($BA:$BA=$BI11)*($BC:$BC=_xlfn.NUMBERVALUE($BJ11)))),""),"")} -> 0 | DM11: {=IF($BK11<>"",IFERROR(AVERAGE(_xlfn._xlws.FILTER($BD:$BD,($BA:$BA=$BI11)*($BC:$BC=_xlfn.NUMBERVALUE($BK11)))),""),"")} -> 16.394444 | DN11: {=IF($BL11<>"",IFERROR(AVERAGE(_xlfn._xlws.FILTER($BD:$BD,($BA:$BA=$BI11)*($BC:$BC=_xlfn.NUMBERVALUE($BL11)))),""),"")} -> 35.916667 | DO11: {=IF($BM11<>"",IFERROR(AVERAGE(_xlfn._xlws.FILTER($BD:$BD,($BA:$BA=$BI11)*($BC:$BC=_xlfn.NUMBERVALUE($BM11)))),""),"")} -> 60.9 | DP11: {=IF($BN11<>"",IFERROR(AVERAGE(_xlfn._xlws.FILTER($BD:$BD,($BA:$BA=$BI11)*($BC:$BC=_xlfn.NUMBERVALUE($BN11)))),""),"")} | DQ11: {=IF($BO11<>"",IFERROR(AVERAGE(_xlfn._xlws.FILTER($BD:$BD,($BA:$BA=$BI11)*($BC:$BC=_xlfn.NUMBERVALUE($BO11)))),""),"")} | DR11: 0 | DS11: 0 | DT11: 0 | DU11: 0 | DX11: {=IF($BJ11<>"",IFERROR(AVERAGE(_xlfn._xlws.FILTER($BE:$BE,($BA:$BA=$BI11)*($BC:$BC=_xlfn.NUMBERVALUE($BJ11)))),""),"")} -> 0 | DY11: {=IF($BK11<>"",IFERROR(AVERAGE(_xlfn._xlws.FILTER($BE:$BE,($BA:$BA=$BI11)*($BC:$BC=_xlfn.NUMBERVALUE($BK11)))),""),"")} -> 0 | DZ11: {=IF($BL11<>"",IFERROR(AVERAGE(_xlfn._xlws.FILTER($BE:$BE,($BA:$BA=$BI11)*($BC:$BC=_xlfn.NUMBERVALUE($BL11)))),""),"")} -> 0 | EA11: {=IF($BM11<>"",IFERROR(AVERAGE(_xlfn._xlws.FILTER($BE:$BE,($BA:$BA=$BI11)*($BC:$BC=_xlfn.NUMBERVALUE($BM11)))),""),"")} -> 0 | EB11: {=IF($BN11<>"",IFERROR(AVERAGE(_xlfn._xlws.FILTER($BE:$BE,($BA:$BA=$BI11)*($BC:$BC=_xlfn.NUMBERVALUE($BN11)))),""),"")} | EC11: {=IF($BO11<>"",IFERROR(AVERAGE(_xlfn._xlws.FILTER($BE:$BE,($BA:$BA=$BI11)*($BC:$BC=_xlfn.NUMBERVALUE($BO11)))),""),"")}
